2018-08-09 16:05:41-0500 [HTTPChannelWithXForwardedFor,4980,54.202.222.59] [EE] [Failure instance: Traceback (failure with no frames): <class 'twisted.internet.error.ConnectionDone'>: Connection was closed cleanly.
2018-08-09 16:05:41-0500 [HTTPChannelWithXForwardedFor,4980,54.202.222.59] [EE] ]
2018-08-09 16:05:41-0500 [HTTPChannelWithXForwardedFor,4980,54.202.222.59] [EE] Caught errback in webserver.py:75.
2018-08-09 16:06:01-0500 [-] Unhandled Error
	Traceback (most recent call last):
	  File "/root/mud/pyenv/local/lib/python2.7/site-packages/twisted/application/app.py", line 364, in startReactor
	    self.config, oldstdout, oldstderr, self.profiler, reactor)
	  File "/root/mud/pyenv/local/lib/python2.7/site-packages/twisted/application/app.py", line 285, in runReactorWithLogging
	    reactor.run()
	  File "/root/mud/pyenv/local/lib/python2.7/site-packages/twisted/internet/base.py", line 1194, in run
	    self.mainLoop()
	  File "/root/mud/pyenv/local/lib/python2.7/site-packages/twisted/internet/base.py", line 1203, in mainLoop
	    self.runUntilCurrent()
	--- <exception caught here> ---
	  File "/root/mud/pyenv/local/lib/python2.7/site-packages/twisted/internet/base.py", line 825, in runUntilCurrent
	    call.func(*call.args, **call.kw)
	  File "/root/mud/pyenv/local/lib/python2.7/site-packages/twisted/internet/tcp.py", line 454, in failIfNotConnected
	    self.connector.connectionFailed(failure.Failure(err))
	  File "/root/mud/pyenv/local/lib/python2.7/site-packages/twisted/internet/base.py", line 1079, in connectionFailed
	    self.factory.clientConnectionFailed(self, reason)
	  File "/root/mud/pyenv/local/lib/python2.7/site-packages/twisted/web/proxy.py", line 122, in clientConnectionFailed
	    self.father.finish()
	  File "/root/mud/pyenv/local/lib/python2.7/site-packages/twisted/web/server.py", line 224, in finish
	    return http.Request.finish(self)
	  File "/root/mud/pyenv/local/lib/python2.7/site-packages/twisted/web/http.py", line 865, in finish
	    "Request.finish called on a request after its connection was lost; "
	exceptions.RuntimeError: Request.finish called on a request after its connection was lost; use Request.notifyFinish to keep track of this.
	
2018-08-09 16:09:40-0500 [HTTPChannelWithXForwardedFor,4982,157.55.39.28] [::] None
2018-08-09 16:09:40-0500 [HTTPChannelWithXForwardedFor,4982,157.55.39.28] [EE] [Failure instance: Traceback (failure with no frames): <class 'twisted.internet.error.ConnectionLost'>: Connection to the other side was lost in a non-clean fashion.
2018-08-09 16:09:40-0500 [HTTPChannelWithXForwardedFor,4982,157.55.39.28] [EE] ]
2018-08-09 16:09:40-0500 [HTTPChannelWithXForwardedFor,4982,157.55.39.28] [EE] Caught errback in webserver.py:75.
2018-08-09 16:09:40-0500 [HTTPChannelWithXForwardedFor,4982,157.55.39.28] [::] None
2018-08-09 16:09:40-0500 [HTTPChannelWithXForwardedFor,4982,157.55.39.28] [EE] [Failure instance: Traceback (failure with no frames): <class 'twisted.internet.error.ConnectionLost'>: Connection to the other side was lost in a non-clean fashion.
2018-08-09 16:09:40-0500 [HTTPChannelWithXForwardedFor,4982,157.55.39.28] [EE] ]
2018-08-09 16:09:40-0500 [HTTPChannelWithXForwardedFor,4982,157.55.39.28] [EE] Caught errback in webserver.py:75.
2018-08-09 16:09:40-0500 [-] Unhandled Error
	Traceback (most recent call last):
	  File "/root/mud/pyenv/local/lib/python2.7/site-packages/twisted/application/app.py", line 364, in startReactor
	    self.config, oldstdout, oldstderr, self.profiler, reactor)
	  File "/root/mud/pyenv/local/lib/python2.7/site-packages/twisted/application/app.py", line 285, in runReactorWithLogging
	    reactor.run()
	  File "/root/mud/pyenv/local/lib/python2.7/site-packages/twisted/internet/base.py", line 1194, in run
	    self.mainLoop()
	  File "/root/mud/pyenv/local/lib/python2.7/site-packages/twisted/internet/base.py", line 1203, in mainLoop
	    self.runUntilCurrent()
	--- <exception caught here> ---
	  File "/root/mud/pyenv/local/lib/python2.7/site-packages/twisted/internet/base.py", line 825, in runUntilCurrent
	    call.func(*call.args, **call.kw)
	  File "/root/mud/pyenv/local/lib/python2.7/site-packages/twisted/internet/tcp.py", line 454, in failIfNotConnected
	    self.connector.connectionFailed(failure.Failure(err))
	  File "/root/mud/pyenv/local/lib/python2.7/site-packages/twisted/internet/base.py", line 1079, in connectionFailed
	    self.factory.clientConnectionFailed(self, reason)
	  File "/root/mud/pyenv/local/lib/python2.7/site-packages/twisted/web/proxy.py", line 122, in clientConnectionFailed
	    self.father.finish()
	  File "/root/mud/pyenv/local/lib/python2.7/site-packages/twisted/web/server.py", line 224, in finish
	    return http.Request.finish(self)
	  File "/root/mud/pyenv/local/lib/python2.7/site-packages/twisted/web/http.py", line 865, in finish
	    "Request.finish called on a request after its connection was lost; "
	exceptions.RuntimeError: Request.finish called on a request after its connection was lost; use Request.notifyFinish to keep track of this.
	
2018-08-09 16:20:32-0500 [HTTPChannelWithXForwardedFor,4985,186.96.255.246] [::] None
2018-08-09 16:20:32-0500 [HTTPChannelWithXForwardedFor,4985,186.96.255.246] [EE] [Failure instance: Traceback (failure with no frames): <class 'twisted.internet.error.ConnectionDone'>: Connection was closed cleanly.
2018-08-09 16:20:32-0500 [HTTPChannelWithXForwardedFor,4985,186.96.255.246] [EE] ]
2018-08-09 16:20:32-0500 [HTTPChannelWithXForwardedFor,4985,186.96.255.246] [EE] Caught errback in webserver.py:75.
2018-08-09 16:20:32-0500 [HTTPChannelWithXForwardedFor,4985,186.96.255.246] [::] None
2018-08-09 16:20:32-0500 [HTTPChannelWithXForwardedFor,4985,186.96.255.246] [EE] [Failure instance: Traceback (failure with no frames): <class 'twisted.internet.error.ConnectionDone'>: Connection was closed cleanly.
2018-08-09 16:20:32-0500 [HTTPChannelWithXForwardedFor,4985,186.96.255.246] [EE] ]
2018-08-09 16:20:32-0500 [HTTPChannelWithXForwardedFor,4985,186.96.255.246] [EE] Caught errback in webserver.py:75.
2018-08-09 16:20:56-0500 [-] Unhandled Error
	Traceback (most recent call last):
	  File "/root/mud/pyenv/local/lib/python2.7/site-packages/twisted/application/app.py", line 364, in startReactor
	    self.config, oldstdout, oldstderr, self.profiler, reactor)
	  File "/root/mud/pyenv/local/lib/python2.7/site-packages/twisted/application/app.py", line 285, in runReactorWithLogging
	    reactor.run()
	  File "/root/mud/pyenv/local/lib/python2.7/site-packages/twisted/internet/base.py", line 1194, in run
	    self.mainLoop()
	  File "/root/mud/pyenv/local/lib/python2.7/site-packages/twisted/internet/base.py", line 1203, in mainLoop
	    self.runUntilCurrent()
	--- <exception caught here> ---
	  File "/root/mud/pyenv/local/lib/python2.7/site-packages/twisted/internet/base.py", line 825, in runUntilCurrent
	    call.func(*call.args, **call.kw)
	  File "/root/mud/pyenv/local/lib/python2.7/site-packages/twisted/internet/tcp.py", line 454, in failIfNotConnected
	    self.connector.connectionFailed(failure.Failure(err))
	  File "/root/mud/pyenv/local/lib/python2.7/site-packages/twisted/internet/base.py", line 1079, in connectionFailed
	    self.factory.clientConnectionFailed(self, reason)
	  File "/root/mud/pyenv/local/lib/python2.7/site-packages/twisted/web/proxy.py", line 122, in clientConnectionFailed
	    self.father.finish()
	  File "/root/mud/pyenv/local/lib/python2.7/site-packages/twisted/web/server.py", line 224, in finish
	    return http.Request.finish(self)
	  File "/root/mud/pyenv/local/lib/python2.7/site-packages/twisted/web/http.py", line 865, in finish
	    "Request.finish called on a request after its connection was lost; "
	exceptions.RuntimeError: Request.finish called on a request after its connection was lost; use Request.notifyFinish to keep track of this.
	
2018-08-09 16:32:15-0500 [HTTPChannelWithXForwardedFor,4986,103.96.51.48] [::] None
2018-08-09 16:32:15-0500 [HTTPChannelWithXForwardedFor,4986,103.96.51.48] [EE] [Failure instance: Traceback (failure with no frames): <class 'twisted.internet.error.ConnectionDone'>: Connection was closed cleanly.
2018-08-09 16:32:15-0500 [HTTPChannelWithXForwardedFor,4986,103.96.51.48] [EE] ]
2018-08-09 16:32:15-0500 [HTTPChannelWithXForwardedFor,4986,103.96.51.48] [EE] Caught errback in webserver.py:75.
2018-08-09 16:32:15-0500 [HTTPChannelWithXForwardedFor,4986,103.96.51.48] [::] None
2018-08-09 16:32:15-0500 [HTTPChannelWithXForwardedFor,4986,103.96.51.48] [EE] [Failure instance: Traceback (failure with no frames): <class 'twisted.internet.error.ConnectionDone'>: Connection was closed cleanly.
2018-08-09 16:32:15-0500 [HTTPChannelWithXForwardedFor,4986,103.96.51.48] [EE] ]
2018-08-09 16:32:15-0500 [HTTPChannelWithXForwardedFor,4986,103.96.51.48] [EE] Caught errback in webserver.py:75.
2018-08-09 16:32:40-0500 [-] Unhandled Error
	Traceback (most recent call last):
	  File "/root/mud/pyenv/local/lib/python2.7/site-packages/twisted/application/app.py", line 364, in startReactor
	    self.config, oldstdout, oldstderr, self.profiler, reactor)
	  File "/root/mud/pyenv/local/lib/python2.7/site-packages/twisted/application/app.py", line 285, in runReactorWithLogging
	    reactor.run()
	  File "/root/mud/pyenv/local/lib/python2.7/site-packages/twisted/internet/base.py", line 1194, in run
	    self.mainLoop()
	  File "/root/mud/pyenv/local/lib/python2.7/site-packages/twisted/internet/base.py", line 1203, in mainLoop
	    self.runUntilCurrent()
	--- <exception caught here> ---
	  File "/root/mud/pyenv/local/lib/python2.7/site-packages/twisted/internet/base.py", line 825, in runUntilCurrent
	    call.func(*call.args, **call.kw)
	  File "/root/mud/pyenv/local/lib/python2.7/site-packages/twisted/internet/tcp.py", line 454, in failIfNotConnected
	    self.connector.connectionFailed(failure.Failure(err))
	  File "/root/mud/pyenv/local/lib/python2.7/site-packages/twisted/internet/base.py", line 1079, in connectionFailed
	    self.factory.clientConnectionFailed(self, reason)
	  File "/root/mud/pyenv/local/lib/python2.7/site-packages/twisted/web/proxy.py", line 122, in clientConnectionFailed
	    self.father.finish()
	  File "/root/mud/pyenv/local/lib/python2.7/site-packages/twisted/web/server.py", line 224, in finish
	    return http.Request.finish(self)
	  File "/root/mud/pyenv/local/lib/python2.7/site-packages/twisted/web/http.py", line 865, in finish
	    "Request.finish called on a request after its connection was lost; "
	exceptions.RuntimeError: Request.finish called on a request after its connection was lost; use Request.notifyFinish to keep track of this.
	
2018-08-09 17:13:44-0500 [HTTPChannelWithXForwardedFor,4987,46.229.168.67] [::] None
2018-08-09 17:13:44-0500 [HTTPChannelWithXForwardedFor,4987,46.229.168.67] [EE] [Failure instance: Traceback (failure with no frames): <class 'twisted.internet.error.ConnectionDone'>: Connection was closed cleanly.
2018-08-09 17:13:44-0500 [HTTPChannelWithXForwardedFor,4987,46.229.168.67] [EE] ]
2018-08-09 17:13:44-0500 [HTTPChannelWithXForwardedFor,4987,46.229.168.67] [EE] Caught errback in webserver.py:75.
2018-08-09 17:13:44-0500 [HTTPChannelWithXForwardedFor,4987,46.229.168.67] [::] None
2018-08-09 17:13:44-0500 [HTTPChannelWithXForwardedFor,4987,46.229.168.67] [EE] [Failure instance: Traceback (failure with no frames): <class 'twisted.internet.error.ConnectionDone'>: Connection was closed cleanly.
2018-08-09 17:13:44-0500 [HTTPChannelWithXForwardedFor,4987,46.229.168.67] [EE] ]
2018-08-09 17:13:44-0500 [HTTPChannelWithXForwardedFor,4987,46.229.168.67] [EE] Caught errback in webserver.py:75.
2018-08-09 17:13:59-0500 [HTTPChannelWithXForwardedFor,4988,46.229.168.67] [::] None
2018-08-09 17:13:59-0500 [HTTPChannelWithXForwardedFor,4988,46.229.168.67] [EE] [Failure instance: Traceback (failure with no frames): <class 'twisted.internet.error.ConnectionDone'>: Connection was closed cleanly.
2018-08-09 17:13:59-0500 [HTTPChannelWithXForwardedFor,4988,46.229.168.67] [EE] ]
2018-08-09 17:13:59-0500 [HTTPChannelWithXForwardedFor,4988,46.229.168.67] [EE] Caught errback in webserver.py:75.
2018-08-09 17:13:59-0500 [HTTPChannelWithXForwardedFor,4988,46.229.168.67] [::] None
2018-08-09 17:13:59-0500 [HTTPChannelWithXForwardedFor,4988,46.229.168.67] [EE] [Failure instance: Traceback (failure with no frames): <class 'twisted.internet.error.ConnectionDone'>: Connection was closed cleanly.
2018-08-09 17:13:59-0500 [HTTPChannelWithXForwardedFor,4988,46.229.168.67] [EE] ]
2018-08-09 17:13:59-0500 [HTTPChannelWithXForwardedFor,4988,46.229.168.67] [EE] Caught errback in webserver.py:75.
2018-08-09 17:13:59-0500 [-] Unhandled Error
	Traceback (most recent call last):
	  File "/root/mud/pyenv/local/lib/python2.7/site-packages/twisted/application/app.py", line 364, in startReactor
	    self.config, oldstdout, oldstderr, self.profiler, reactor)
	  File "/root/mud/pyenv/local/lib/python2.7/site-packages/twisted/application/app.py", line 285, in runReactorWithLogging
	    reactor.run()
	  File "/root/mud/pyenv/local/lib/python2.7/site-packages/twisted/internet/base.py", line 1194, in run
	    self.mainLoop()
	  File "/root/mud/pyenv/local/lib/python2.7/site-packages/twisted/internet/base.py", line 1203, in mainLoop
	    self.runUntilCurrent()
	--- <exception caught here> ---
	  File "/root/mud/pyenv/local/lib/python2.7/site-packages/twisted/internet/base.py", line 825, in runUntilCurrent
	    call.func(*call.args, **call.kw)
	  File "/root/mud/pyenv/local/lib/python2.7/site-packages/twisted/internet/tcp.py", line 454, in failIfNotConnected
	    self.connector.connectionFailed(failure.Failure(err))
	  File "/root/mud/pyenv/local/lib/python2.7/site-packages/twisted/internet/base.py", line 1079, in connectionFailed
	    self.factory.clientConnectionFailed(self, reason)
	  File "/root/mud/pyenv/local/lib/python2.7/site-packages/twisted/web/proxy.py", line 122, in clientConnectionFailed
	    self.father.finish()
	  File "/root/mud/pyenv/local/lib/python2.7/site-packages/twisted/web/server.py", line 224, in finish
	    return http.Request.finish(self)
	  File "/root/mud/pyenv/local/lib/python2.7/site-packages/twisted/web/http.py", line 865, in finish
	    "Request.finish called on a request after its connection was lost; "
	exceptions.RuntimeError: Request.finish called on a request after its connection was lost; use Request.notifyFinish to keep track of this.
	
2018-08-09 17:14:14-0500 [-] Unhandled Error
	Traceback (most recent call last):
	  File "/root/mud/pyenv/local/lib/python2.7/site-packages/twisted/application/app.py", line 364, in startReactor
	    self.config, oldstdout, oldstderr, self.profiler, reactor)
	  File "/root/mud/pyenv/local/lib/python2.7/site-packages/twisted/application/app.py", line 285, in runReactorWithLogging
	    reactor.run()
	  File "/root/mud/pyenv/local/lib/python2.7/site-packages/twisted/internet/base.py", line 1194, in run
	    self.mainLoop()
	  File "/root/mud/pyenv/local/lib/python2.7/site-packages/twisted/internet/base.py", line 1203, in mainLoop
	    self.runUntilCurrent()
	--- <exception caught here> ---
	  File "/root/mud/pyenv/local/lib/python2.7/site-packages/twisted/internet/base.py", line 825, in runUntilCurrent
	    call.func(*call.args, **call.kw)
	  File "/root/mud/pyenv/local/lib/python2.7/site-packages/twisted/internet/tcp.py", line 454, in failIfNotConnected
	    self.connector.connectionFailed(failure.Failure(err))
	  File "/root/mud/pyenv/local/lib/python2.7/site-packages/twisted/internet/base.py", line 1079, in connectionFailed
	    self.factory.clientConnectionFailed(self, reason)
	  File "/root/mud/pyenv/local/lib/python2.7/site-packages/twisted/web/proxy.py", line 122, in clientConnectionFailed
	    self.father.finish()
	  File "/root/mud/pyenv/local/lib/python2.7/site-packages/twisted/web/server.py", line 224, in finish
	    return http.Request.finish(self)
	  File "/root/mud/pyenv/local/lib/python2.7/site-packages/twisted/web/http.py", line 865, in finish
	    "Request.finish called on a request after its connection was lost; "
	exceptions.RuntimeError: Request.finish called on a request after its connection was lost; use Request.notifyFinish to keep track of this.
	
2018-08-09 17:35:28-0500 [HTTPChannelWithXForwardedFor,4991,60.191.38.77] [::] None
2018-08-09 17:35:28-0500 [HTTPChannelWithXForwardedFor,4991,60.191.38.77] [EE] [Failure instance: Traceback (failure with no frames): <class 'twisted.internet.error.ConnectionDone'>: Connection was closed cleanly.
2018-08-09 17:35:28-0500 [HTTPChannelWithXForwardedFor,4991,60.191.38.77] [EE] ]
2018-08-09 17:35:28-0500 [HTTPChannelWithXForwardedFor,4991,60.191.38.77] [EE] Caught errback in webserver.py:75.
2018-08-09 17:35:28-0500 [HTTPChannelWithXForwardedFor,4991,60.191.38.77] [::] None
2018-08-09 17:35:28-0500 [HTTPChannelWithXForwardedFor,4991,60.191.38.77] [EE] [Failure instance: Traceback (failure with no frames): <class 'twisted.internet.error.ConnectionDone'>: Connection was closed cleanly.
2018-08-09 17:35:28-0500 [HTTPChannelWithXForwardedFor,4991,60.191.38.77] [EE] ]
2018-08-09 17:35:28-0500 [HTTPChannelWithXForwardedFor,4991,60.191.38.77] [EE] Caught errback in webserver.py:75.
2018-08-09 17:35:39-0500 [-] Unhandled Error
	Traceback (most recent call last):
	  File "/root/mud/pyenv/local/lib/python2.7/site-packages/twisted/application/app.py", line 364, in startReactor
	    self.config, oldstdout, oldstderr, self.profiler, reactor)
	  File "/root/mud/pyenv/local/lib/python2.7/site-packages/twisted/application/app.py", line 285, in runReactorWithLogging
	    reactor.run()
	  File "/root/mud/pyenv/local/lib/python2.7/site-packages/twisted/internet/base.py", line 1194, in run
	    self.mainLoop()
	  File "/root/mud/pyenv/local/lib/python2.7/site-packages/twisted/internet/base.py", line 1203, in mainLoop
	    self.runUntilCurrent()
	--- <exception caught here> ---
	  File "/root/mud/pyenv/local/lib/python2.7/site-packages/twisted/internet/base.py", line 825, in runUntilCurrent
	    call.func(*call.args, **call.kw)
	  File "/root/mud/pyenv/local/lib/python2.7/site-packages/twisted/internet/tcp.py", line 454, in failIfNotConnected
	    self.connector.connectionFailed(failure.Failure(err))
	  File "/root/mud/pyenv/local/lib/python2.7/site-packages/twisted/internet/base.py", line 1079, in connectionFailed
	    self.factory.clientConnectionFailed(self, reason)
	  File "/root/mud/pyenv/local/lib/python2.7/site-packages/twisted/web/proxy.py", line 122, in clientConnectionFailed
	    self.father.finish()
	  File "/root/mud/pyenv/local/lib/python2.7/site-packages/twisted/web/server.py", line 224, in finish
	    return http.Request.finish(self)
	  File "/root/mud/pyenv/local/lib/python2.7/site-packages/twisted/web/http.py", line 865, in finish
	    "Request.finish called on a request after its connection was lost; "
	exceptions.RuntimeError: Request.finish called on a request after its connection was lost; use Request.notifyFinish to keep track of this.
	
2018-08-09 18:02:10-0500 [HTTPChannelWithXForwardedFor,5001,138.185.164.99] [::] None
2018-08-09 18:02:10-0500 [HTTPChannelWithXForwardedFor,5001,138.185.164.99] [EE] [Failure instance: Traceback (failure with no frames): <class 'twisted.internet.error.ConnectionDone'>: Connection was closed cleanly.
2018-08-09 18:02:10-0500 [HTTPChannelWithXForwardedFor,5001,138.185.164.99] [EE] ]
2018-08-09 18:02:10-0500 [HTTPChannelWithXForwardedFor,5001,138.185.164.99] [EE] Caught errback in webserver.py:75.
2018-08-09 18:02:10-0500 [HTTPChannelWithXForwardedFor,5001,138.185.164.99] [::] None
2018-08-09 18:02:10-0500 [HTTPChannelWithXForwardedFor,5001,138.185.164.99] [EE] [Failure instance: Traceback (failure with no frames): <class 'twisted.internet.error.ConnectionDone'>: Connection was closed cleanly.
2018-08-09 18:02:10-0500 [HTTPChannelWithXForwardedFor,5001,138.185.164.99] [EE] ]
2018-08-09 18:02:10-0500 [HTTPChannelWithXForwardedFor,5001,138.185.164.99] [EE] Caught errback in webserver.py:75.
2018-08-09 18:02:34-0500 [-] Unhandled Error
	Traceback (most recent call last):
	  File "/root/mud/pyenv/local/lib/python2.7/site-packages/twisted/application/app.py", line 364, in startReactor
	    self.config, oldstdout, oldstderr, self.profiler, reactor)
	  File "/root/mud/pyenv/local/lib/python2.7/site-packages/twisted/application/app.py", line 285, in runReactorWithLogging
	    reactor.run()
	  File "/root/mud/pyenv/local/lib/python2.7/site-packages/twisted/internet/base.py", line 1194, in run
	    self.mainLoop()
	  File "/root/mud/pyenv/local/lib/python2.7/site-packages/twisted/internet/base.py", line 1203, in mainLoop
	    self.runUntilCurrent()
	--- <exception caught here> ---
	  File "/root/mud/pyenv/local/lib/python2.7/site-packages/twisted/internet/base.py", line 825, in runUntilCurrent
	    call.func(*call.args, **call.kw)
	  File "/root/mud/pyenv/local/lib/python2.7/site-packages/twisted/internet/tcp.py", line 454, in failIfNotConnected
	    self.connector.connectionFailed(failure.Failure(err))
	  File "/root/mud/pyenv/local/lib/python2.7/site-packages/twisted/internet/base.py", line 1079, in connectionFailed
	    self.factory.clientConnectionFailed(self, reason)
	  File "/root/mud/pyenv/local/lib/python2.7/site-packages/twisted/web/proxy.py", line 122, in clientConnectionFailed
	    self.father.finish()
	  File "/root/mud/pyenv/local/lib/python2.7/site-packages/twisted/web/server.py", line 224, in finish
	    return http.Request.finish(self)
	  File "/root/mud/pyenv/local/lib/python2.7/site-packages/twisted/web/http.py", line 865, in finish
	    "Request.finish called on a request after its connection was lost; "
	exceptions.RuntimeError: Request.finish called on a request after its connection was lost; use Request.notifyFinish to keep track of this.
	
2018-08-09 18:03:11-0500 [HTTPChannelWithXForwardedFor,5002,177.54.196.146] [::] None
2018-08-09 18:03:11-0500 [HTTPChannelWithXForwardedFor,5002,177.54.196.146] [EE] [Failure instance: Traceback (failure with no frames): <class 'twisted.internet.error.ConnectionDone'>: Connection was closed cleanly.
2018-08-09 18:03:11-0500 [HTTPChannelWithXForwardedFor,5002,177.54.196.146] [EE] ]
2018-08-09 18:03:11-0500 [HTTPChannelWithXForwardedFor,5002,177.54.196.146] [EE] Caught errback in webserver.py:75.
2018-08-09 18:03:11-0500 [HTTPChannelWithXForwardedFor,5002,177.54.196.146] [::] None
2018-08-09 18:03:11-0500 [HTTPChannelWithXForwardedFor,5002,177.54.196.146] [EE] [Failure instance: Traceback (failure with no frames): <class 'twisted.internet.error.ConnectionDone'>: Connection was closed cleanly.
2018-08-09 18:03:11-0500 [HTTPChannelWithXForwardedFor,5002,177.54.196.146] [EE] ]
2018-08-09 18:03:11-0500 [HTTPChannelWithXForwardedFor,5002,177.54.196.146] [EE] Caught errback in webserver.py:75.
2018-08-09 18:03:35-0500 [-] Unhandled Error
	Traceback (most recent call last):
	  File "/root/mud/pyenv/local/lib/python2.7/site-packages/twisted/application/app.py", line 364, in startReactor
	    self.config, oldstdout, oldstderr, self.profiler, reactor)
	  File "/root/mud/pyenv/local/lib/python2.7/site-packages/twisted/application/app.py", line 285, in runReactorWithLogging
	    reactor.run()
	  File "/root/mud/pyenv/local/lib/python2.7/site-packages/twisted/internet/base.py", line 1194, in run
	    self.mainLoop()
	  File "/root/mud/pyenv/local/lib/python2.7/site-packages/twisted/internet/base.py", line 1203, in mainLoop
	    self.runUntilCurrent()
	--- <exception caught here> ---
	  File "/root/mud/pyenv/local/lib/python2.7/site-packages/twisted/internet/base.py", line 825, in runUntilCurrent
	    call.func(*call.args, **call.kw)
	  File "/root/mud/pyenv/local/lib/python2.7/site-packages/twisted/internet/tcp.py", line 454, in failIfNotConnected
	    self.connector.connectionFailed(failure.Failure(err))
	  File "/root/mud/pyenv/local/lib/python2.7/site-packages/twisted/internet/base.py", line 1079, in connectionFailed
	    self.factory.clientConnectionFailed(self, reason)
	  File "/root/mud/pyenv/local/lib/python2.7/site-packages/twisted/web/proxy.py", line 122, in clientConnectionFailed
	    self.father.finish()
	  File "/root/mud/pyenv/local/lib/python2.7/site-packages/twisted/web/server.py", line 224, in finish
	    return http.Request.finish(self)
	  File "/root/mud/pyenv/local/lib/python2.7/site-packages/twisted/web/http.py", line 865, in finish
	    "Request.finish called on a request after its connection was lost; "
	exceptions.RuntimeError: Request.finish called on a request after its connection was lost; use Request.notifyFinish to keep track of this.
	
2018-08-09 18:43:53-0500 [HTTPChannelWithXForwardedFor,5003,79.30.233.191] [::] None
2018-08-09 18:43:53-0500 [HTTPChannelWithXForwardedFor,5003,79.30.233.191] [EE] [Failure instance: Traceback (failure with no frames): <class 'twisted.internet.error.ConnectionDone'>: Connection was closed cleanly.
2018-08-09 18:43:53-0500 [HTTPChannelWithXForwardedFor,5003,79.30.233.191] [EE] ]
2018-08-09 18:43:53-0500 [HTTPChannelWithXForwardedFor,5003,79.30.233.191] [EE] Caught errback in webserver.py:75.
2018-08-09 18:43:53-0500 [HTTPChannelWithXForwardedFor,5003,79.30.233.191] [::] None
2018-08-09 18:43:53-0500 [HTTPChannelWithXForwardedFor,5003,79.30.233.191] [EE] [Failure instance: Traceback (failure with no frames): <class 'twisted.internet.error.ConnectionDone'>: Connection was closed cleanly.
2018-08-09 18:43:53-0500 [HTTPChannelWithXForwardedFor,5003,79.30.233.191] [EE] ]
2018-08-09 18:43:53-0500 [HTTPChannelWithXForwardedFor,5003,79.30.233.191] [EE] Caught errback in webserver.py:75.
2018-08-09 18:44:17-0500 [-] Unhandled Error
	Traceback (most recent call last):
	  File "/root/mud/pyenv/local/lib/python2.7/site-packages/twisted/application/app.py", line 364, in startReactor
	    self.config, oldstdout, oldstderr, self.profiler, reactor)
	  File "/root/mud/pyenv/local/lib/python2.7/site-packages/twisted/application/app.py", line 285, in runReactorWithLogging
	    reactor.run()
	  File "/root/mud/pyenv/local/lib/python2.7/site-packages/twisted/internet/base.py", line 1194, in run
	    self.mainLoop()
	  File "/root/mud/pyenv/local/lib/python2.7/site-packages/twisted/internet/base.py", line 1203, in mainLoop
	    self.runUntilCurrent()
	--- <exception caught here> ---
	  File "/root/mud/pyenv/local/lib/python2.7/site-packages/twisted/internet/base.py", line 825, in runUntilCurrent
	    call.func(*call.args, **call.kw)
	  File "/root/mud/pyenv/local/lib/python2.7/site-packages/twisted/internet/tcp.py", line 454, in failIfNotConnected
	    self.connector.connectionFailed(failure.Failure(err))
	  File "/root/mud/pyenv/local/lib/python2.7/site-packages/twisted/internet/base.py", line 1079, in connectionFailed
	    self.factory.clientConnectionFailed(self, reason)
	  File "/root/mud/pyenv/local/lib/python2.7/site-packages/twisted/web/proxy.py", line 122, in clientConnectionFailed
	    self.father.finish()
	  File "/root/mud/pyenv/local/lib/python2.7/site-packages/twisted/web/server.py", line 224, in finish
	    return http.Request.finish(self)
	  File "/root/mud/pyenv/local/lib/python2.7/site-packages/twisted/web/http.py", line 865, in finish
	    "Request.finish called on a request after its connection was lost; "
	exceptions.RuntimeError: Request.finish called on a request after its connection was lost; use Request.notifyFinish to keep track of this.
	
2018-08-09 19:21:43-0500 [HTTPChannelWithXForwardedFor,5006,77.239.155.118] [::] None
2018-08-09 19:21:43-0500 [HTTPChannelWithXForwardedFor,5006,77.239.155.118] [EE] [Failure instance: Traceback (failure with no frames): <class 'twisted.internet.error.ConnectionDone'>: Connection was closed cleanly.
2018-08-09 19:21:43-0500 [HTTPChannelWithXForwardedFor,5006,77.239.155.118] [EE] ]
2018-08-09 19:21:43-0500 [HTTPChannelWithXForwardedFor,5006,77.239.155.118] [EE] Caught errback in webserver.py:75.
2018-08-09 19:21:43-0500 [HTTPChannelWithXForwardedFor,5006,77.239.155.118] [::] None
2018-08-09 19:21:43-0500 [HTTPChannelWithXForwardedFor,5006,77.239.155.118] [EE] [Failure instance: Traceback (failure with no frames): <class 'twisted.internet.error.ConnectionDone'>: Connection was closed cleanly.
2018-08-09 19:21:43-0500 [HTTPChannelWithXForwardedFor,5006,77.239.155.118] [EE] ]
2018-08-09 19:21:43-0500 [HTTPChannelWithXForwardedFor,5006,77.239.155.118] [EE] Caught errback in webserver.py:75.
2018-08-09 19:22:13-0500 [-] Unhandled Error
	Traceback (most recent call last):
	  File "/root/mud/pyenv/local/lib/python2.7/site-packages/twisted/application/app.py", line 364, in startReactor
	    self.config, oldstdout, oldstderr, self.profiler, reactor)
	  File "/root/mud/pyenv/local/lib/python2.7/site-packages/twisted/application/app.py", line 285, in runReactorWithLogging
	    reactor.run()
	  File "/root/mud/pyenv/local/lib/python2.7/site-packages/twisted/internet/base.py", line 1194, in run
	    self.mainLoop()
	  File "/root/mud/pyenv/local/lib/python2.7/site-packages/twisted/internet/base.py", line 1203, in mainLoop
	    self.runUntilCurrent()
	--- <exception caught here> ---
	  File "/root/mud/pyenv/local/lib/python2.7/site-packages/twisted/internet/base.py", line 825, in runUntilCurrent
	    call.func(*call.args, **call.kw)
	  File "/root/mud/pyenv/local/lib/python2.7/site-packages/twisted/internet/tcp.py", line 454, in failIfNotConnected
	    self.connector.connectionFailed(failure.Failure(err))
	  File "/root/mud/pyenv/local/lib/python2.7/site-packages/twisted/internet/base.py", line 1079, in connectionFailed
	    self.factory.clientConnectionFailed(self, reason)
	  File "/root/mud/pyenv/local/lib/python2.7/site-packages/twisted/web/proxy.py", line 122, in clientConnectionFailed
	    self.father.finish()
	  File "/root/mud/pyenv/local/lib/python2.7/site-packages/twisted/web/server.py", line 224, in finish
	    return http.Request.finish(self)
	  File "/root/mud/pyenv/local/lib/python2.7/site-packages/twisted/web/http.py", line 865, in finish
	    "Request.finish called on a request after its connection was lost; "
	exceptions.RuntimeError: Request.finish called on a request after its connection was lost; use Request.notifyFinish to keep track of this.
	
2018-08-09 19:28:04-0500 [HTTPChannelWithXForwardedFor,5008,37.237.199.7] [::] None
2018-08-09 19:28:04-0500 [HTTPChannelWithXForwardedFor,5008,37.237.199.7] [EE] [Failure instance: Traceback (failure with no frames): <class 'twisted.internet.error.ConnectionDone'>: Connection was closed cleanly.
2018-08-09 19:28:04-0500 [HTTPChannelWithXForwardedFor,5008,37.237.199.7] [EE] ]
2018-08-09 19:28:04-0500 [HTTPChannelWithXForwardedFor,5008,37.237.199.7] [EE] Caught errback in webserver.py:75.
2018-08-09 19:28:04-0500 [HTTPChannelWithXForwardedFor,5008,37.237.199.7] [::] None
2018-08-09 19:28:04-0500 [HTTPChannelWithXForwardedFor,5008,37.237.199.7] [EE] [Failure instance: Traceback (failure with no frames): <class 'twisted.internet.error.ConnectionDone'>: Connection was closed cleanly.
2018-08-09 19:28:04-0500 [HTTPChannelWithXForwardedFor,5008,37.237.199.7] [EE] ]
2018-08-09 19:28:04-0500 [HTTPChannelWithXForwardedFor,5008,37.237.199.7] [EE] Caught errback in webserver.py:75.
2018-08-09 19:28:04-0500 [-] Unhandled Error
	Traceback (most recent call last):
	  File "/root/mud/pyenv/local/lib/python2.7/site-packages/twisted/application/app.py", line 364, in startReactor
	    self.config, oldstdout, oldstderr, self.profiler, reactor)
	  File "/root/mud/pyenv/local/lib/python2.7/site-packages/twisted/application/app.py", line 285, in runReactorWithLogging
	    reactor.run()
	  File "/root/mud/pyenv/local/lib/python2.7/site-packages/twisted/internet/base.py", line 1194, in run
	    self.mainLoop()
	  File "/root/mud/pyenv/local/lib/python2.7/site-packages/twisted/internet/base.py", line 1203, in mainLoop
	    self.runUntilCurrent()
	--- <exception caught here> ---
	  File "/root/mud/pyenv/local/lib/python2.7/site-packages/twisted/internet/base.py", line 825, in runUntilCurrent
	    call.func(*call.args, **call.kw)
	  File "/root/mud/pyenv/local/lib/python2.7/site-packages/twisted/internet/tcp.py", line 454, in failIfNotConnected
	    self.connector.connectionFailed(failure.Failure(err))
	  File "/root/mud/pyenv/local/lib/python2.7/site-packages/twisted/internet/base.py", line 1079, in connectionFailed
	    self.factory.clientConnectionFailed(self, reason)
	  File "/root/mud/pyenv/local/lib/python2.7/site-packages/twisted/web/proxy.py", line 122, in clientConnectionFailed
	    self.father.finish()
	  File "/root/mud/pyenv/local/lib/python2.7/site-packages/twisted/web/server.py", line 224, in finish
	    return http.Request.finish(self)
	  File "/root/mud/pyenv/local/lib/python2.7/site-packages/twisted/web/http.py", line 865, in finish
	    "Request.finish called on a request after its connection was lost; "
	exceptions.RuntimeError: Request.finish called on a request after its connection was lost; use Request.notifyFinish to keep track of this.
	
2018-08-09 19:51:15-0500 [HTTPChannelWithXForwardedFor,5021,109.121.162.163] [::] None
2018-08-09 19:51:15-0500 [HTTPChannelWithXForwardedFor,5021,109.121.162.163] [EE] [Failure instance: Traceback (failure with no frames): <class 'twisted.internet.error.ConnectionDone'>: Connection was closed cleanly.
2018-08-09 19:51:15-0500 [HTTPChannelWithXForwardedFor,5021,109.121.162.163] [EE] ]
2018-08-09 19:51:15-0500 [HTTPChannelWithXForwardedFor,5021,109.121.162.163] [EE] Caught errback in webserver.py:75.
2018-08-09 19:51:15-0500 [HTTPChannelWithXForwardedFor,5021,109.121.162.163] [::] None
2018-08-09 19:51:15-0500 [HTTPChannelWithXForwardedFor,5021,109.121.162.163] [EE] [Failure instance: Traceback (failure with no frames): <class 'twisted.internet.error.ConnectionDone'>: Connection was closed cleanly.
2018-08-09 19:51:15-0500 [HTTPChannelWithXForwardedFor,5021,109.121.162.163] [EE] ]
2018-08-09 19:51:15-0500 [HTTPChannelWithXForwardedFor,5021,109.121.162.163] [EE] Caught errback in webserver.py:75.
2018-08-09 19:51:39-0500 [-] Unhandled Error
	Traceback (most recent call last):
	  File "/root/mud/pyenv/local/lib/python2.7/site-packages/twisted/application/app.py", line 364, in startReactor
	    self.config, oldstdout, oldstderr, self.profiler, reactor)
	  File "/root/mud/pyenv/local/lib/python2.7/site-packages/twisted/application/app.py", line 285, in runReactorWithLogging
	    reactor.run()
	  File "/root/mud/pyenv/local/lib/python2.7/site-packages/twisted/internet/base.py", line 1194, in run
	    self.mainLoop()
	  File "/root/mud/pyenv/local/lib/python2.7/site-packages/twisted/internet/base.py", line 1203, in mainLoop
	    self.runUntilCurrent()
	--- <exception caught here> ---
	  File "/root/mud/pyenv/local/lib/python2.7/site-packages/twisted/internet/base.py", line 825, in runUntilCurrent
	    call.func(*call.args, **call.kw)
	  File "/root/mud/pyenv/local/lib/python2.7/site-packages/twisted/internet/tcp.py", line 454, in failIfNotConnected
	    self.connector.connectionFailed(failure.Failure(err))
	  File "/root/mud/pyenv/local/lib/python2.7/site-packages/twisted/internet/base.py", line 1079, in connectionFailed
	    self.factory.clientConnectionFailed(self, reason)
	  File "/root/mud/pyenv/local/lib/python2.7/site-packages/twisted/web/proxy.py", line 122, in clientConnectionFailed
	    self.father.finish()
	  File "/root/mud/pyenv/local/lib/python2.7/site-packages/twisted/web/server.py", line 224, in finish
	    return http.Request.finish(self)
	  File "/root/mud/pyenv/local/lib/python2.7/site-packages/twisted/web/http.py", line 865, in finish
	    "Request.finish called on a request after its connection was lost; "
	exceptions.RuntimeError: Request.finish called on a request after its connection was lost; use Request.notifyFinish to keep track of this.
	
2018-08-09 20:16:00-0500 [HTTPChannelWithXForwardedFor,5023,209.198.28.73] [::] None
2018-08-09 20:16:00-0500 [HTTPChannelWithXForwardedFor,5023,209.198.28.73] [EE] [Failure instance: Traceback (failure with no frames): <class 'twisted.internet.error.ConnectionDone'>: Connection was closed cleanly.
2018-08-09 20:16:00-0500 [HTTPChannelWithXForwardedFor,5023,209.198.28.73] [EE] ]
2018-08-09 20:16:00-0500 [HTTPChannelWithXForwardedFor,5023,209.198.28.73] [EE] Caught errback in webserver.py:75.
2018-08-09 20:16:00-0500 [HTTPChannelWithXForwardedFor,5023,209.198.28.73] [::] None
2018-08-09 20:16:00-0500 [HTTPChannelWithXForwardedFor,5023,209.198.28.73] [EE] [Failure instance: Traceback (failure with no frames): <class 'twisted.internet.error.ConnectionDone'>: Connection was closed cleanly.
2018-08-09 20:16:00-0500 [HTTPChannelWithXForwardedFor,5023,209.198.28.73] [EE] ]
2018-08-09 20:16:00-0500 [HTTPChannelWithXForwardedFor,5023,209.198.28.73] [EE] Caught errback in webserver.py:75.
2018-08-09 20:16:24-0500 [-] Unhandled Error
	Traceback (most recent call last):
	  File "/root/mud/pyenv/local/lib/python2.7/site-packages/twisted/application/app.py", line 364, in startReactor
	    self.config, oldstdout, oldstderr, self.profiler, reactor)
	  File "/root/mud/pyenv/local/lib/python2.7/site-packages/twisted/application/app.py", line 285, in runReactorWithLogging
	    reactor.run()
	  File "/root/mud/pyenv/local/lib/python2.7/site-packages/twisted/internet/base.py", line 1194, in run
	    self.mainLoop()
	  File "/root/mud/pyenv/local/lib/python2.7/site-packages/twisted/internet/base.py", line 1203, in mainLoop
	    self.runUntilCurrent()
	--- <exception caught here> ---
	  File "/root/mud/pyenv/local/lib/python2.7/site-packages/twisted/internet/base.py", line 825, in runUntilCurrent
	    call.func(*call.args, **call.kw)
	  File "/root/mud/pyenv/local/lib/python2.7/site-packages/twisted/internet/tcp.py", line 454, in failIfNotConnected
	    self.connector.connectionFailed(failure.Failure(err))
	  File "/root/mud/pyenv/local/lib/python2.7/site-packages/twisted/internet/base.py", line 1079, in connectionFailed
	    self.factory.clientConnectionFailed(self, reason)
	  File "/root/mud/pyenv/local/lib/python2.7/site-packages/twisted/web/proxy.py", line 122, in clientConnectionFailed
	    self.father.finish()
	  File "/root/mud/pyenv/local/lib/python2.7/site-packages/twisted/web/server.py", line 224, in finish
	    return http.Request.finish(self)
	  File "/root/mud/pyenv/local/lib/python2.7/site-packages/twisted/web/http.py", line 865, in finish
	    "Request.finish called on a request after its connection was lost; "
	exceptions.RuntimeError: Request.finish called on a request after its connection was lost; use Request.notifyFinish to keep track of this.
	
2018-08-09 21:02:28-0500 [HTTPChannelWithXForwardedFor,5025,195.110.35.242] [::] None
2018-08-09 21:02:28-0500 [HTTPChannelWithXForwardedFor,5025,195.110.35.242] [EE] [Failure instance: Traceback (failure with no frames): <class 'twisted.internet.error.ConnectionDone'>: Connection was closed cleanly.
2018-08-09 21:02:28-0500 [HTTPChannelWithXForwardedFor,5025,195.110.35.242] [EE] ]
2018-08-09 21:02:28-0500 [HTTPChannelWithXForwardedFor,5025,195.110.35.242] [EE] Caught errback in webserver.py:75.
2018-08-09 21:02:28-0500 [HTTPChannelWithXForwardedFor,5025,195.110.35.242] [::] None
2018-08-09 21:02:28-0500 [HTTPChannelWithXForwardedFor,5025,195.110.35.242] [EE] [Failure instance: Traceback (failure with no frames): <class 'twisted.internet.error.ConnectionDone'>: Connection was closed cleanly.
2018-08-09 21:02:28-0500 [HTTPChannelWithXForwardedFor,5025,195.110.35.242] [EE] ]
2018-08-09 21:02:28-0500 [HTTPChannelWithXForwardedFor,5025,195.110.35.242] [EE] Caught errback in webserver.py:75.
2018-08-09 21:02:43-0500 [-] Unhandled Error
	Traceback (most recent call last):
	  File "/root/mud/pyenv/local/lib/python2.7/site-packages/twisted/application/app.py", line 364, in startReactor
	    self.config, oldstdout, oldstderr, self.profiler, reactor)
	  File "/root/mud/pyenv/local/lib/python2.7/site-packages/twisted/application/app.py", line 285, in runReactorWithLogging
	    reactor.run()
	  File "/root/mud/pyenv/local/lib/python2.7/site-packages/twisted/internet/base.py", line 1194, in run
	    self.mainLoop()
	  File "/root/mud/pyenv/local/lib/python2.7/site-packages/twisted/internet/base.py", line 1203, in mainLoop
	    self.runUntilCurrent()
	--- <exception caught here> ---
	  File "/root/mud/pyenv/local/lib/python2.7/site-packages/twisted/internet/base.py", line 825, in runUntilCurrent
	    call.func(*call.args, **call.kw)
	  File "/root/mud/pyenv/local/lib/python2.7/site-packages/twisted/internet/tcp.py", line 454, in failIfNotConnected
	    self.connector.connectionFailed(failure.Failure(err))
	  File "/root/mud/pyenv/local/lib/python2.7/site-packages/twisted/internet/base.py", line 1079, in connectionFailed
	    self.factory.clientConnectionFailed(self, reason)
	  File "/root/mud/pyenv/local/lib/python2.7/site-packages/twisted/web/proxy.py", line 122, in clientConnectionFailed
	    self.father.finish()
	  File "/root/mud/pyenv/local/lib/python2.7/site-packages/twisted/web/server.py", line 224, in finish
	    return http.Request.finish(self)
	  File "/root/mud/pyenv/local/lib/python2.7/site-packages/twisted/web/http.py", line 865, in finish
	    "Request.finish called on a request after its connection was lost; "
	exceptions.RuntimeError: Request.finish called on a request after its connection was lost; use Request.notifyFinish to keep track of this.
	
2018-08-09 21:04:02-0500 [HTTPChannelWithXForwardedFor,5026,195.110.35.242] [::] None
2018-08-09 21:04:02-0500 [HTTPChannelWithXForwardedFor,5026,195.110.35.242] [EE] [Failure instance: Traceback (failure with no frames): <class 'twisted.internet.error.ConnectionDone'>: Connection was closed cleanly.
2018-08-09 21:04:02-0500 [HTTPChannelWithXForwardedFor,5026,195.110.35.242] [EE] ]
2018-08-09 21:04:02-0500 [HTTPChannelWithXForwardedFor,5026,195.110.35.242] [EE] Caught errback in webserver.py:75.
2018-08-09 21:04:02-0500 [HTTPChannelWithXForwardedFor,5026,195.110.35.242] [::] None
2018-08-09 21:04:02-0500 [HTTPChannelWithXForwardedFor,5026,195.110.35.242] [EE] [Failure instance: Traceback (failure with no frames): <class 'twisted.internet.error.ConnectionDone'>: Connection was closed cleanly.
2018-08-09 21:04:02-0500 [HTTPChannelWithXForwardedFor,5026,195.110.35.242] [EE] ]
2018-08-09 21:04:02-0500 [HTTPChannelWithXForwardedFor,5026,195.110.35.242] [EE] Caught errback in webserver.py:75.
2018-08-09 21:04:17-0500 [-] Unhandled Error
	Traceback (most recent call last):
	  File "/root/mud/pyenv/local/lib/python2.7/site-packages/twisted/application/app.py", line 364, in startReactor
	    self.config, oldstdout, oldstderr, self.profiler, reactor)
	  File "/root/mud/pyenv/local/lib/python2.7/site-packages/twisted/application/app.py", line 285, in runReactorWithLogging
	    reactor.run()
	  File "/root/mud/pyenv/local/lib/python2.7/site-packages/twisted/internet/base.py", line 1194, in run
	    self.mainLoop()
	  File "/root/mud/pyenv/local/lib/python2.7/site-packages/twisted/internet/base.py", line 1203, in mainLoop
	    self.runUntilCurrent()
	--- <exception caught here> ---
	  File "/root/mud/pyenv/local/lib/python2.7/site-packages/twisted/internet/base.py", line 825, in runUntilCurrent
	    call.func(*call.args, **call.kw)
	  File "/root/mud/pyenv/local/lib/python2.7/site-packages/twisted/internet/tcp.py", line 454, in failIfNotConnected
	    self.connector.connectionFailed(failure.Failure(err))
	  File "/root/mud/pyenv/local/lib/python2.7/site-packages/twisted/internet/base.py", line 1079, in connectionFailed
	    self.factory.clientConnectionFailed(self, reason)
	  File "/root/mud/pyenv/local/lib/python2.7/site-packages/twisted/web/proxy.py", line 122, in clientConnectionFailed
	    self.father.finish()
	  File "/root/mud/pyenv/local/lib/python2.7/site-packages/twisted/web/server.py", line 224, in finish
	    return http.Request.finish(self)
	  File "/root/mud/pyenv/local/lib/python2.7/site-packages/twisted/web/http.py", line 865, in finish
	    "Request.finish called on a request after its connection was lost; "
	exceptions.RuntimeError: Request.finish called on a request after its connection was lost; use Request.notifyFinish to keep track of this.
	
2018-08-09 21:22:02-0500 [HTTPChannelWithXForwardedFor,5030,54.36.150.86] [::] None
2018-08-09 21:22:02-0500 [HTTPChannelWithXForwardedFor,5030,54.36.150.86] [EE] [Failure instance: Traceback (failure with no frames): <class 'twisted.internet.error.ConnectionDone'>: Connection was closed cleanly.
2018-08-09 21:22:02-0500 [HTTPChannelWithXForwardedFor,5030,54.36.150.86] [EE] ]
2018-08-09 21:22:02-0500 [HTTPChannelWithXForwardedFor,5030,54.36.150.86] [EE] Caught errback in webserver.py:75.
2018-08-09 21:22:02-0500 [HTTPChannelWithXForwardedFor,5030,54.36.150.86] [::] None
2018-08-09 21:22:02-0500 [HTTPChannelWithXForwardedFor,5030,54.36.150.86] [EE] [Failure instance: Traceback (failure with no frames): <class 'twisted.internet.error.ConnectionDone'>: Connection was closed cleanly.
2018-08-09 21:22:02-0500 [HTTPChannelWithXForwardedFor,5030,54.36.150.86] [EE] ]
2018-08-09 21:22:02-0500 [HTTPChannelWithXForwardedFor,5030,54.36.150.86] [EE] Caught errback in webserver.py:75.
2018-08-09 21:22:02-0500 [-] Unhandled Error
	Traceback (most recent call last):
	  File "/root/mud/pyenv/local/lib/python2.7/site-packages/twisted/application/app.py", line 364, in startReactor
	    self.config, oldstdout, oldstderr, self.profiler, reactor)
	  File "/root/mud/pyenv/local/lib/python2.7/site-packages/twisted/application/app.py", line 285, in runReactorWithLogging
	    reactor.run()
	  File "/root/mud/pyenv/local/lib/python2.7/site-packages/twisted/internet/base.py", line 1194, in run
	    self.mainLoop()
	  File "/root/mud/pyenv/local/lib/python2.7/site-packages/twisted/internet/base.py", line 1203, in mainLoop
	    self.runUntilCurrent()
	--- <exception caught here> ---
	  File "/root/mud/pyenv/local/lib/python2.7/site-packages/twisted/internet/base.py", line 825, in runUntilCurrent
	    call.func(*call.args, **call.kw)
	  File "/root/mud/pyenv/local/lib/python2.7/site-packages/twisted/internet/tcp.py", line 454, in failIfNotConnected
	    self.connector.connectionFailed(failure.Failure(err))
	  File "/root/mud/pyenv/local/lib/python2.7/site-packages/twisted/internet/base.py", line 1079, in connectionFailed
	    self.factory.clientConnectionFailed(self, reason)
	  File "/root/mud/pyenv/local/lib/python2.7/site-packages/twisted/web/proxy.py", line 122, in clientConnectionFailed
	    self.father.finish()
	  File "/root/mud/pyenv/local/lib/python2.7/site-packages/twisted/web/server.py", line 224, in finish
	    return http.Request.finish(self)
	  File "/root/mud/pyenv/local/lib/python2.7/site-packages/twisted/web/http.py", line 865, in finish
	    "Request.finish called on a request after its connection was lost; "
	exceptions.RuntimeError: Request.finish called on a request after its connection was lost; use Request.notifyFinish to keep track of this.
	
2018-08-09 23:14:51-0500 [HTTPChannelWithXForwardedFor,5050,50.53.114.246] [::] None
2018-08-09 23:14:51-0500 [HTTPChannelWithXForwardedFor,5050,50.53.114.246] [EE] [Failure instance: Traceback (failure with no frames): <class 'twisted.internet.error.ConnectionDone'>: Connection was closed cleanly.
2018-08-09 23:14:51-0500 [HTTPChannelWithXForwardedFor,5050,50.53.114.246] [EE] ]
2018-08-09 23:14:51-0500 [HTTPChannelWithXForwardedFor,5050,50.53.114.246] [EE] Caught errback in webserver.py:75.
2018-08-09 23:14:51-0500 [HTTPChannelWithXForwardedFor,5050,50.53.114.246] [::] None
2018-08-09 23:14:51-0500 [HTTPChannelWithXForwardedFor,5050,50.53.114.246] [EE] [Failure instance: Traceback (failure with no frames): <class 'twisted.internet.error.ConnectionDone'>: Connection was closed cleanly.
2018-08-09 23:14:51-0500 [HTTPChannelWithXForwardedFor,5050,50.53.114.246] [EE] ]
2018-08-09 23:14:51-0500 [HTTPChannelWithXForwardedFor,5050,50.53.114.246] [EE] Caught errback in webserver.py:75.
2018-08-09 23:15:06-0500 [HTTPChannelWithXForwardedFor,5051,50.53.114.246] [::] None
2018-08-09 23:15:06-0500 [HTTPChannelWithXForwardedFor,5051,50.53.114.246] [EE] [Failure instance: Traceback (failure with no frames): <class 'twisted.internet.error.ConnectionDone'>: Connection was closed cleanly.
2018-08-09 23:15:06-0500 [HTTPChannelWithXForwardedFor,5051,50.53.114.246] [EE] ]
2018-08-09 23:15:06-0500 [HTTPChannelWithXForwardedFor,5051,50.53.114.246] [EE] Caught errback in webserver.py:75.
2018-08-09 23:15:06-0500 [HTTPChannelWithXForwardedFor,5051,50.53.114.246] [::] None
2018-08-09 23:15:06-0500 [HTTPChannelWithXForwardedFor,5051,50.53.114.246] [EE] [Failure instance: Traceback (failure with no frames): <class 'twisted.internet.error.ConnectionDone'>: Connection was closed cleanly.
2018-08-09 23:15:06-0500 [HTTPChannelWithXForwardedFor,5051,50.53.114.246] [EE] ]
2018-08-09 23:15:06-0500 [HTTPChannelWithXForwardedFor,5051,50.53.114.246] [EE] Caught errback in webserver.py:75.
2018-08-09 23:15:16-0500 [-] Unhandled Error
	Traceback (most recent call last):
	  File "/root/mud/pyenv/local/lib/python2.7/site-packages/twisted/application/app.py", line 364, in startReactor
	    self.config, oldstdout, oldstderr, self.profiler, reactor)
	  File "/root/mud/pyenv/local/lib/python2.7/site-packages/twisted/application/app.py", line 285, in runReactorWithLogging
	    reactor.run()
	  File "/root/mud/pyenv/local/lib/python2.7/site-packages/twisted/internet/base.py", line 1194, in run
	    self.mainLoop()
	  File "/root/mud/pyenv/local/lib/python2.7/site-packages/twisted/internet/base.py", line 1203, in mainLoop
	    self.runUntilCurrent()
	--- <exception caught here> ---
	  File "/root/mud/pyenv/local/lib/python2.7/site-packages/twisted/internet/base.py", line 825, in runUntilCurrent
	    call.func(*call.args, **call.kw)
	  File "/root/mud/pyenv/local/lib/python2.7/site-packages/twisted/internet/tcp.py", line 454, in failIfNotConnected
	    self.connector.connectionFailed(failure.Failure(err))
	  File "/root/mud/pyenv/local/lib/python2.7/site-packages/twisted/internet/base.py", line 1079, in connectionFailed
	    self.factory.clientConnectionFailed(self, reason)
	  File "/root/mud/pyenv/local/lib/python2.7/site-packages/twisted/web/proxy.py", line 122, in clientConnectionFailed
	    self.father.finish()
	  File "/root/mud/pyenv/local/lib/python2.7/site-packages/twisted/web/server.py", line 224, in finish
	    return http.Request.finish(self)
	  File "/root/mud/pyenv/local/lib/python2.7/site-packages/twisted/web/http.py", line 865, in finish
	    "Request.finish called on a request after its connection was lost; "
	exceptions.RuntimeError: Request.finish called on a request after its connection was lost; use Request.notifyFinish to keep track of this.
	
2018-08-09 23:15:21-0500 [-] Unhandled Error
	Traceback (most recent call last):
	  File "/root/mud/pyenv/local/lib/python2.7/site-packages/twisted/application/app.py", line 364, in startReactor
	    self.config, oldstdout, oldstderr, self.profiler, reactor)
	  File "/root/mud/pyenv/local/lib/python2.7/site-packages/twisted/application/app.py", line 285, in runReactorWithLogging
	    reactor.run()
	  File "/root/mud/pyenv/local/lib/python2.7/site-packages/twisted/internet/base.py", line 1194, in run
	    self.mainLoop()
	  File "/root/mud/pyenv/local/lib/python2.7/site-packages/twisted/internet/base.py", line 1203, in mainLoop
	    self.runUntilCurrent()
	--- <exception caught here> ---
	  File "/root/mud/pyenv/local/lib/python2.7/site-packages/twisted/internet/base.py", line 825, in runUntilCurrent
	    call.func(*call.args, **call.kw)
	  File "/root/mud/pyenv/local/lib/python2.7/site-packages/twisted/internet/tcp.py", line 454, in failIfNotConnected
	    self.connector.connectionFailed(failure.Failure(err))
	  File "/root/mud/pyenv/local/lib/python2.7/site-packages/twisted/internet/base.py", line 1079, in connectionFailed
	    self.factory.clientConnectionFailed(self, reason)
	  File "/root/mud/pyenv/local/lib/python2.7/site-packages/twisted/web/proxy.py", line 122, in clientConnectionFailed
	    self.father.finish()
	  File "/root/mud/pyenv/local/lib/python2.7/site-packages/twisted/web/server.py", line 224, in finish
	    return http.Request.finish(self)
	  File "/root/mud/pyenv/local/lib/python2.7/site-packages/twisted/web/http.py", line 865, in finish
	    "Request.finish called on a request after its connection was lost; "
	exceptions.RuntimeError: Request.finish called on a request after its connection was lost; use Request.notifyFinish to keep track of this.
	
